<?xml version="1.0" ?>
<robot name="two_wheeled_robot" xmlns:xacro="http://ros.org/wiki/xacro">

  <!-- ****************** ROBOT CONSTANTS *******************************  -->
  <!-- Define the size of the robot's main chassis in meters -->

  <!-- Defina o tamanho do chassi principal do robô em metros -->
  <xacro:property name="base_width" value="0.14"/>
  <xacro:property name="base_length" value="0.14"/>
  <xacro:property name="base_height" value="0.05"/>
	
  <!-- Define the shape of the robot's two back wheels in meters -->

  <!-- Defina o formato das duas rodas traseiras do robô em metros -->
  <xacro:property name="wheel_radius" value="0.07"/>
  <xacro:property name="wheel_width" value="0.025"/>

  <!-- x-axis points forward, y-axis points to left, z-axis points upwards -->
  <!-- Define the gap between the wheel and chassis along y-axis in meters -->


<!-- eixo x aponta para frente, eixo y aponta para esquerda, eixo z aponta para cima -->
  <!-- Defina a distância entre a roda e o chassi ao longo do eixo y em metros -->
  <xacro:property name="wheel_ygap" value="0.035"/>

  <!-- Position the wheels along the z-axis -->
  <xacro:property name="wheel_zoff" value="0.05"/>

  <!-- Position the wheels along the x-axis -->
  <xacro:property name="wheel_xoff" value="0.221"/>

  <!-- Position the caster wheel along the x-axis -->
  <xacro:property name="caster_xoff" value="0.217"/>

  <!-- Define intertial property macros  -->

  <!-- Definir macros de propriedades inerciais -->
  <xacro:macro name="box_inertia" params="m w h d">
    <inertial>
      <origin xyz="0 0 0" rpy="${pi/2} 0 ${pi/2}"/>
      <mass value="${m}"/>
      <inertia ixx="${(m/12) * (h*h + d*d)}" ixy="0.0" ixz="0.0" iyy="${(m/12) * (w*w + d*d)}" iyz="0.0" izz="${(m/12) * (w*w + h*h)}"/>
    </inertial>
  </xacro:macro>

  <xacro:macro name="cylinder_inertia" params="m r h">
    <inertial>
      <origin xyz="0 0 0" rpy="${pi/2} 0 0" />
      <mass value="${m}"/>
      <inertia ixx="${(m/12) * (3*r*r + h*h)}" ixy = "0" ixz = "0" iyy="${(m/12) * (3*r*r + h*h)}" iyz = "0" izz="${(m/2) * (r*r)}"/>
    </inertial>
  </xacro:macro>

  <xacro:macro name="sphere_inertia" params="m r">
    <inertial>
      <mass value="${m}"/>
      <inertia ixx="${(2/5) * m * (r*r)}" ixy="0.0" ixz="0.0" iyy="${(2/5) * m * (r*r)}" iyz="0.0" izz="${(2/5) * m * (r*r)}"/>
    </inertial>
  </xacro:macro>

  <!-- ****************** ROBOT BASE FOOTPRINT ***************************  -->
  <!-- Define the center of the main robot chassis projected on the ground -->	


  <!-- ****************** PEGADA DA BASE DO ROBÔ ************************* ** -->
  <!-- Definir o centro do chassi principal do robô projetado no solo -->

  <link name="base_footprint"/>

  <!-- The base footprint of the robot is located underneath the chassis -->

  <!-- A base do robô está localizada abaixo do chassi -->
  <joint name="base_joint" type="fixed">
    <parent link="base_footprint"/>
    <child link="base_link" />
    <origin xyz="0.0 0.0 ${(wheel_radius+wheel_zoff)}" rpy="0 0 0"/>
  </joint>

  <!-- ********************** ROBOT BASE *********************************  -->
  <link name="base_link">
    <visual>
      <origin xyz="0 0 -0.05" rpy="1.5707963267949 0 3.141592654"/>
      <geometry>
        <mesh filename="package://two_wheeled_robot/meshes/robot_base.stl" />
      </geometry>
      <material name="Red">
        <color rgba="${255/255} ${0/255} ${0/255} 1.0"/>
      </material>
    </visual>

    <collision>
      <geometry>
        <box size="${base_length} ${base_width} ${base_height}"/>
      </geometry>
    </collision>

    <xacro:box_inertia m="40.0" w="${base_width}" d="${base_length}" h="${base_height}"/>
    
  </link>

  <gazebo reference="base_link">
    <material>Gazebo/Red</material>
  </gazebo>

  <!-- *********************** DRIVE WHEELS ******************************  -->

  <xacro:macro name="wheel" params="prefix x_reflect y_reflect">
    <link name="${prefix}_link">
      <visual>
        <origin xyz="0 0 0" rpy="1.5707963267949 0 0"/>
        <geometry>
            <cylinder radius="${wheel_radius}" length="${wheel_width}"/>
        </geometry>
        <material name="White">
          <color rgba="${255/255} ${255/255} ${255/255} 1.0"/>
        </material>
      </visual>
      
      <collision>
        <origin xyz="0 0 0" rpy="${pi/2} 0 0"/>
        <geometry>
          <cylinder radius="${wheel_radius}" length="${wheel_width}"/>
        </geometry>
      </collision>
      
      <xacro:cylinder_inertia m="110.5" r="${wheel_radius}" h="${wheel_width}"/>
      
    </link>

    <!-- Connect the wheels to the base_link at the appropriate location, and 
         define a continuous joint to allow the wheels to freely rotate about
         an axis -->

<!-- Conecte as rodas ao base_link no local apropriado e
         definir uma junta contínua para permitir que as rodas girem livremente em torno
         um eixo -->



    <joint name="${prefix}_joint" type="revolute">
      <parent link="base_link"/>
      <child link="${prefix}_link"/>
      <origin xyz="${x_reflect*wheel_xoff} ${y_reflect*(base_width/2+wheel_ygap)} ${-wheel_zoff}" rpy="0 0 0"/>
      <limit upper="3.1415" lower="-3.1415" effort="30" velocity="5.0"/>
      <axis xyz="0 1 0"/>
    </joint>
  </xacro:macro>

  <!-- Instantiate two wheels using the macro we just made through the 
       xacro:wheel tags. We also define the parameters to have one wheel
       on both sides at the back of our robot (i.e. x_reflect=-1). -->


       <!-- Instancie duas rodas usando a macro que acabamos de fazer através do
       xacro: tags de roda. Também definimos os parâmetros para ter uma roda
       em ambos os lados na parte traseira do nosso robô (ou seja, x_reflect=-1). -->
  <xacro:wheel prefix="drivewhl_l" x_reflect="-1" y_reflect="1" />
  <xacro:wheel prefix="drivewhl_r" x_reflect="-1" y_reflect="-1" />

  <!-- *********************** CASTER WHEEL ******************************  -->
  <!-- We add a caster wheel. It will be modeled as sphere.
       We define the wheel’s geometry, material and the joint to connect it to 
       base_link at the appropriate location. -->


       <!-- *********************** RODA DE RODÍZIO ********************* ********* -->
  <!-- Adicionamos uma roda giratória. Será modelado como uma esfera.
       Definimos a geometria da roda, o material e a junta para conectá-la
       base_link no local apropriado. -->
  <link name="front_caster">
    <visual>
      <geometry>
        <sphere radius="${(wheel_radius+wheel_zoff-(base_height/2))}"/>
      </geometry>
      <material name="White">
        <color rgba="${255/255} ${255/255} ${255/255} 1.0"/>
      </material>
    </visual>
    <collision>
      <origin xyz="0 0 0" rpy="0 0 0"/>
      <geometry>
        <sphere radius="${(wheel_radius+wheel_zoff-(base_height/2))}"/>
      </geometry>
    </collision>
    <xacro:sphere_inertia m="10.05" r="${(wheel_radius+wheel_zoff-(base_height/2))}"/>
  </link>

  <gazebo reference="front_caster">
    <mu1>0.01</mu1>
    <mu2>0.01</mu2>
    <material>Gazebo/White</material>
  </gazebo>

  <joint name="caster_joint" type="fixed">
    <parent link="base_link"/>
    <child link="front_caster"/>
    <origin xyz="${caster_xoff} 0.0 ${-(base_height/2)}" rpy="0 0 0"/>
  </joint>
  
  <!-- *********************** IMU SETUP *********************************  -->
  <!-- Each sensor must be attached to a link.                              --> 

  <!-- *********************** CONFIGURAÇÃO DA IMU ********************* ************ -->
  <!-- Cada sensor deve ser conectado a um link. -->
  
  <joint name="imu_joint" type="fixed">
    <parent link="base_link"/>
    <child link="imu_link"/>
    <origin xyz="-0.10 0 0.05" rpy="0 0 0"/>
  </joint>

  <link name="imu_link"/>

  <!-- *********************** LIDAR SETUP **********************************  -->
  <joint name="lidar_joint" type="fixed">
    <parent link="base_link"/>
    <child link="lidar_link"/>
    <origin xyz="0.215 0 0.13" rpy="0 0 0"/>
  </joint>

  <link name="lidar_link">
  
    <collision>
     <origin xyz="0 0 0" rpy="0 0 0"/>
     <geometry>
      <cylinder radius="0.0508" length="0.18"/>
     </geometry>
    </collision>
    
    <visual>
     <origin xyz="0 0 0" rpy="0 0 0"/>
     <geometry>
      <cylinder radius="0.0508" length="0.18"/>
     </geometry>
     <material name="Black">
          <color rgba="${0/255} ${0/255} ${0/255} 1.0"/>
     </material>
    </visual>
    
    <inertial>
      <mass value="0.114" />
      <origin xyz="0 0 0" rpy="0 0 0"/>
      <inertia ixx="0.001" ixy="0" ixz="0" iyy="0.001" iyz="0" izz="0.001" />
    </inertial>
  </link>

</robot>
